<?xml version="1.0" encoding="UTF-8"?>
<!-- Generated by org.testng.reporters.JUnitXMLReporter -->
<testsuite ignored="4" hostname="LAPTOP-552TM191" failures="1" tests="1" name="Default test" time="3.631" errors="0" timestamp="09 May 2023 15:00:45 GMT">
  <testcase classname="api_tests.CustomerManagement" name="incorrectAuth" time="2.396">
    <failure type="java.lang.AssertionError" message="expected:&amp;lt;401&amp;gt; but was:&amp;lt;200&amp;gt;">
      <![CDATA[java.lang.AssertionError: expected:<401> but was:<200>
at org.junit.Assert.fail(Assert.java:89)
at org.junit.Assert.failNotEquals(Assert.java:835)
at org.junit.Assert.assertEquals(Assert.java:647)
at org.junit.Assert.assertEquals(Assert.java:633)
at api_tests.CustomerManagement.incorrectAuth(CustomerManagement.java:121)
at java.base/jdk.internal.reflect.NativeMethodAccessorImpl.invoke0(Native Method)
at java.base/jdk.internal.reflect.NativeMethodAccessorImpl.invoke(NativeMethodAccessorImpl.java:62)
at java.base/jdk.internal.reflect.DelegatingMethodAccessorImpl.invoke(DelegatingMethodAccessorImpl.java:43)
at java.base/java.lang.reflect.Method.invoke(Method.java:566)
at org.testng.internal.MethodInvocationHelper.invokeMethod(MethodInvocationHelper.java:124)
at org.testng.internal.Invoker.invokeMethod(Invoker.java:583)
at org.testng.internal.Invoker.invokeTestMethod(Invoker.java:719)
at org.testng.internal.Invoker.invokeTestMethods(Invoker.java:989)
at org.testng.internal.TestMethodWorker.invokeTestMethods(TestMethodWorker.java:125)
at org.testng.internal.TestMethodWorker.run(TestMethodWorker.java:109)
at org.testng.TestRunner.privateRun(TestRunner.java:648)
at org.testng.TestRunner.run(TestRunner.java:505)
at org.testng.SuiteRunner.runTest(SuiteRunner.java:455)
at org.testng.SuiteRunner.runSequentially(SuiteRunner.java:450)
at org.testng.SuiteRunner.privateRun(SuiteRunner.java:415)
at org.testng.SuiteRunner.run(SuiteRunner.java:364)
at org.testng.SuiteRunnerWorker.runSuite(SuiteRunnerWorker.java:52)
at org.testng.SuiteRunnerWorker.run(SuiteRunnerWorker.java:84)
at org.testng.TestNG.runSuitesSequentially(TestNG.java:1208)
at org.testng.TestNG.runSuitesLocally(TestNG.java:1137)
at org.testng.TestNG.runSuites(TestNG.java:1049)
at org.testng.TestNG.run(TestNG.java:1017)
at org.testng.remote.AbstractRemoteTestNG.run(AbstractRemoteTestNG.java:115)
at org.testng.remote.RemoteTestNG.initAndRun(RemoteTestNG.java:251)
at org.testng.remote.RemoteTestNG.main(RemoteTestNG.java:77)
]]>
    </failure>
  </testcase> <!-- incorrectAuth -->
  <testcase classname="api_tests.CustomerManagement" name="createCustomer" time="0.0">
    <ignored/>
  </testcase> <!-- createCustomer -->
  <testcase classname="api_tests.CustomerManagement" name="incorrectEndpoint" time="0.0">
    <ignored/>
  </testcase> <!-- incorrectEndpoint -->
  <testcase classname="api_tests.CustomerManagement" name="incorrectRequestBody" time="0.0">
    <ignored/>
  </testcase> <!-- incorrectRequestBody -->
  <testcase classname="api_tests.CustomerManagement" name="login" time="0.0">
    <ignored/>
  </testcase> <!-- login -->
</testsuite> <!-- Default test -->
