<?xml version="1.0" encoding="UTF-8"?>
<testng-results ignored="4" total="5" passed="0" failed="1" skipped="0">
  <reporter-output>
  </reporter-output>
  <suite started-at="2023-05-09T15:00:42Z" name="Default suite" finished-at="2023-05-09T15:00:45Z" duration-ms="3631">
    <groups>
    </groups>
    <test started-at="2023-05-09T15:00:42Z" name="Default test" finished-at="2023-05-09T15:00:45Z" duration-ms="3631">
      <class name="api_tests.CustomerManagement">
        <test-method is-config="true" signature="setup()[pri:0, instance:api_tests.CustomerManagement@6d07a63d]" started-at="2023-05-09T15:00:42Z" name="setup" finished-at="2023-05-09T15:00:43Z" duration-ms="1204" status="PASS">
          <reporter-output>
          </reporter-output>
        </test-method> <!-- setup -->
        <test-method signature="incorrectAuth()[pri:0, instance:api_tests.CustomerManagement@6d07a63d]" started-at="2023-05-09T15:00:43Z" name="incorrectAuth" finished-at="2023-05-09T15:00:45Z" duration-ms="2396" status="FAIL">
          <exception class="java.lang.AssertionError">
            <message>
              <![CDATA[expected:<401> but was:<200>]]>
            </message>
            <full-stacktrace>
              <![CDATA[java.lang.AssertionError: expected:<401> but was:<200>
at org.junit.Assert.fail(Assert.java:89)
at org.junit.Assert.failNotEquals(Assert.java:835)
at org.junit.Assert.assertEquals(Assert.java:647)
at org.junit.Assert.assertEquals(Assert.java:633)
at api_tests.CustomerManagement.incorrectAuth(CustomerManagement.java:121)
at java.base/jdk.internal.reflect.NativeMethodAccessorImpl.invoke0(Native Method)
at java.base/jdk.internal.reflect.NativeMethodAccessorImpl.invoke(NativeMethodAccessorImpl.java:62)
at java.base/jdk.internal.reflect.DelegatingMethodAccessorImpl.invoke(DelegatingMethodAccessorImpl.java:43)
at java.base/java.lang.reflect.Method.invoke(Method.java:566)
at org.testng.internal.MethodInvocationHelper.invokeMethod(MethodInvocationHelper.java:124)
at org.testng.internal.Invoker.invokeMethod(Invoker.java:583)
at org.testng.internal.Invoker.invokeTestMethod(Invoker.java:719)
at org.testng.internal.Invoker.invokeTestMethods(Invoker.java:989)
at org.testng.internal.TestMethodWorker.invokeTestMethods(TestMethodWorker.java:125)
at org.testng.internal.TestMethodWorker.run(TestMethodWorker.java:109)
at org.testng.TestRunner.privateRun(TestRunner.java:648)
at org.testng.TestRunner.run(TestRunner.java:505)
at org.testng.SuiteRunner.runTest(SuiteRunner.java:455)
at org.testng.SuiteRunner.runSequentially(SuiteRunner.java:450)
at org.testng.SuiteRunner.privateRun(SuiteRunner.java:415)
at org.testng.SuiteRunner.run(SuiteRunner.java:364)
at org.testng.SuiteRunnerWorker.runSuite(SuiteRunnerWorker.java:52)
at org.testng.SuiteRunnerWorker.run(SuiteRunnerWorker.java:84)
at org.testng.TestNG.runSuitesSequentially(TestNG.java:1208)
at org.testng.TestNG.runSuitesLocally(TestNG.java:1137)
at org.testng.TestNG.runSuites(TestNG.java:1049)
at org.testng.TestNG.run(TestNG.java:1017)
at org.testng.remote.AbstractRemoteTestNG.run(AbstractRemoteTestNG.java:115)
at org.testng.remote.RemoteTestNG.initAndRun(RemoteTestNG.java:251)
at org.testng.remote.RemoteTestNG.main(RemoteTestNG.java:77)
]]>
            </full-stacktrace>
          </exception> <!-- java.lang.AssertionError -->
          <reporter-output>
          </reporter-output>
        </test-method> <!-- incorrectAuth -->
      </class> <!-- api_tests.CustomerManagement -->
    </test> <!-- Default test -->
  </suite> <!-- Default suite -->
</testng-results>
